cpu-bind=MASK - nlpgpu07, task  0  0 [32270]: mask 0xff000000ff set
cpu-bind=MASK - nlpgpu07, task  0  0 [32288]: mask 0xff000000ff set
Traceback (most recent call last):
  File "/home1/a/adilsha/miniconda3/lib/python3.12/site-packages/huggingface_hub/utils/_http.py", line 406, in hf_raise_for_status
    response.raise_for_status()
  File "/home1/a/adilsha/miniconda3/lib/python3.12/site-packages/requests/models.py", line 1024, in raise_for_status
    raise HTTPError(http_error_msg, response=self)
requests.exceptions.HTTPError: 401 Client Error: Unauthorized for url: https://huggingface.co/google/gemma-2-9b-it/resolve/main/config.json

The above exception was the direct cause of the following exception:

Traceback (most recent call last):
  File "/home1/a/adilsha/miniconda3/lib/python3.12/site-packages/transformers/utils/hub.py", line 403, in cached_file
    resolved_file = hf_hub_download(
                    ^^^^^^^^^^^^^^^^
  File "/home1/a/adilsha/miniconda3/lib/python3.12/site-packages/huggingface_hub/utils/_deprecation.py", line 101, in inner_f
    return f(*args, **kwargs)
           ^^^^^^^^^^^^^^^^^^
  File "/home1/a/adilsha/miniconda3/lib/python3.12/site-packages/huggingface_hub/utils/_validators.py", line 114, in _inner_fn
    return fn(*args, **kwargs)
           ^^^^^^^^^^^^^^^^^^^
  File "/home1/a/adilsha/miniconda3/lib/python3.12/site-packages/huggingface_hub/file_download.py", line 1232, in hf_hub_download
    return _hf_hub_download_to_cache_dir(
           ^^^^^^^^^^^^^^^^^^^^^^^^^^^^^^
  File "/home1/a/adilsha/miniconda3/lib/python3.12/site-packages/huggingface_hub/file_download.py", line 1339, in _hf_hub_download_to_cache_dir
    _raise_on_head_call_error(head_call_error, force_download, local_files_only)
  File "/home1/a/adilsha/miniconda3/lib/python3.12/site-packages/huggingface_hub/file_download.py", line 1854, in _raise_on_head_call_error
    raise head_call_error
  File "/home1/a/adilsha/miniconda3/lib/python3.12/site-packages/huggingface_hub/file_download.py", line 1746, in _get_metadata_or_catch_error
    metadata = get_hf_file_metadata(
               ^^^^^^^^^^^^^^^^^^^^^
  File "/home1/a/adilsha/miniconda3/lib/python3.12/site-packages/huggingface_hub/utils/_validators.py", line 114, in _inner_fn
    return fn(*args, **kwargs)
           ^^^^^^^^^^^^^^^^^^^
  File "/home1/a/adilsha/miniconda3/lib/python3.12/site-packages/huggingface_hub/file_download.py", line 1666, in get_hf_file_metadata
    r = _request_wrapper(
        ^^^^^^^^^^^^^^^^^
  File "/home1/a/adilsha/miniconda3/lib/python3.12/site-packages/huggingface_hub/file_download.py", line 364, in _request_wrapper
    response = _request_wrapper(
               ^^^^^^^^^^^^^^^^^
  File "/home1/a/adilsha/miniconda3/lib/python3.12/site-packages/huggingface_hub/file_download.py", line 388, in _request_wrapper
    hf_raise_for_status(response)
  File "/home1/a/adilsha/miniconda3/lib/python3.12/site-packages/huggingface_hub/utils/_http.py", line 423, in hf_raise_for_status
    raise _format(GatedRepoError, message, response) from e
huggingface_hub.errors.GatedRepoError: 401 Client Error. (Request ID: Root=1-6701ee12-192f130c313760866df0b72b;bef9d315-5fc4-42de-949b-15fcd84f92a7)

Cannot access gated repo for url https://huggingface.co/google/gemma-2-9b-it/resolve/main/config.json.
Access to model google/gemma-2-9b-it is restricted. You must have access to it and be authenticated to access it. Please log in.

The above exception was the direct cause of the following exception:

Traceback (most recent call last):
  File "/mnt/nlpgridio3/data/aceAttorney/source/llama_simulator_closedLLM.py", line 177, in <module>
    asyncio.run(main())
  File "/home1/a/adilsha/miniconda3/lib/python3.12/asyncio/runners.py", line 194, in run
    return runner.run(main)
           ^^^^^^^^^^^^^^^^
  File "/home1/a/adilsha/miniconda3/lib/python3.12/asyncio/runners.py", line 118, in run
    return self._loop.run_until_complete(task)
           ^^^^^^^^^^^^^^^^^^^^^^^^^^^^^^^^^^^
  File "/home1/a/adilsha/miniconda3/lib/python3.12/asyncio/base_events.py", line 687, in run_until_complete
    return future.result()
           ^^^^^^^^^^^^^^^
  File "/mnt/nlpgridio3/data/aceAttorney/source/llama_simulator_closedLLM.py", line 162, in main
    outputs = await simulate(args.model, prompt, case_data)
              ^^^^^^^^^^^^^^^^^^^^^^^^^^^^^^^^^^^^^^^^^^^^^
  File "/mnt/nlpgridio3/data/aceAttorney/source/llama_simulator_closedLLM.py", line 136, in simulate
    action = await get_model_action(model, prompt, turn_data, court_record)
             ^^^^^^^^^^^^^^^^^^^^^^^^^^^^^^^^^^^^^^^^^^^^^^^^^^^^^^^^^^^^^^
  File "/mnt/nlpgridio3/data/aceAttorney/source/llama_simulator_closedLLM.py", line 65, in get_model_action
    response = await run_model(model, full_prompt)
               ^^^^^^^^^^^^^^^^^^^^^^^^^^^^^^^^^^^
  File "/mnt/nlpgridio3/data/aceAttorney/source/llama_run_llm_model.py", line 11, in run_model
    generator = pipeline("text-generation", model=model_name, device=0)  # Use device=0 for GPU
                ^^^^^^^^^^^^^^^^^^^^^^^^^^^^^^^^^^^^^^^^^^^^^^^^^^^^^^^
  File "/home1/a/adilsha/miniconda3/lib/python3.12/site-packages/transformers/pipelines/__init__.py", line 805, in pipeline
    config = AutoConfig.from_pretrained(
             ^^^^^^^^^^^^^^^^^^^^^^^^^^^
  File "/home1/a/adilsha/miniconda3/lib/python3.12/site-packages/transformers/models/auto/configuration_auto.py", line 1006, in from_pretrained
    config_dict, unused_kwargs = PretrainedConfig.get_config_dict(pretrained_model_name_or_path, **kwargs)
                                 ^^^^^^^^^^^^^^^^^^^^^^^^^^^^^^^^^^^^^^^^^^^^^^^^^^^^^^^^^^^^^^^^^^^^^^^^^
  File "/home1/a/adilsha/miniconda3/lib/python3.12/site-packages/transformers/configuration_utils.py", line 567, in get_config_dict
    config_dict, kwargs = cls._get_config_dict(pretrained_model_name_or_path, **kwargs)
                          ^^^^^^^^^^^^^^^^^^^^^^^^^^^^^^^^^^^^^^^^^^^^^^^^^^^^^^^^^^^^^
  File "/home1/a/adilsha/miniconda3/lib/python3.12/site-packages/transformers/configuration_utils.py", line 626, in _get_config_dict
    resolved_config_file = cached_file(
                           ^^^^^^^^^^^^
  File "/home1/a/adilsha/miniconda3/lib/python3.12/site-packages/transformers/utils/hub.py", line 421, in cached_file
    raise EnvironmentError(
OSError: You are trying to access a gated repo.
Make sure to have access to it at https://huggingface.co/google/gemma-2-9b-it.
401 Client Error. (Request ID: Root=1-6701ee12-192f130c313760866df0b72b;bef9d315-5fc4-42de-949b-15fcd84f92a7)

Cannot access gated repo for url https://huggingface.co/google/gemma-2-9b-it/resolve/main/config.json.
Access to model google/gemma-2-9b-it is restricted. You must have access to it and be authenticated to access it. Please log in.
srun: error: nlpgpu07: task 0: Exited with exit code 1
